[2025-01-01 15:21:08,758: INFO: main: >>>>>>stage DATA INGESTION STAGE started<<<<<<]
[2025-01-01 15:21:08,769: INFO: common: yaml file : config\config.yaml loaded successfully]
[2025-01-01 15:21:08,777: ERROR: main: yaml file is empty]
Traceback (most recent call last):
  File "C:\Users\sunny\Desktop\MLOps\Data_science_project1\src\datascience\utils\common.py", line 29, in read_yaml
    return ConfigBox(content)
           ^^^^^^^^^^^^^^^^^^
  File "box\\box.py", line 296, in box.box.Box.__init__
box.exceptions.BoxValueError: First argument must be mapping or iterable

During handling of the above exception, another exception occurred:

Traceback (most recent call last):
  File "C:\Users\sunny\Desktop\MLOps\Data_science_project1\main.py", line 8, in <module>
    obj.initiate_data_ingestion()
  File "C:\Users\sunny\Desktop\MLOps\Data_science_project1\src\datascience\pipeline\data_ingestion_pipeline.py", line 12, in initiate_data_ingestion
    config=ConfigurationManager()
           ^^^^^^^^^^^^^^^^^^^^^^
  File "C:\Users\sunny\Desktop\MLOps\Data_science_project1\src\datascience\config\configuration.py", line 11, in __init__
    self.config=read_yaml(config_filepath)
                ^^^^^^^^^^^^^^^^^^^^^^^^^^
  File "C:\Users\sunny\AppData\Local\Programs\Python\Python311\Lib\site-packages\ensure\main.py", line 872, in __call__
    return_val = self.f(*args, **kwargs)
                 ^^^^^^^^^^^^^^^^^^^^^^^
  File "C:\Users\sunny\Desktop\MLOps\Data_science_project1\src\datascience\utils\common.py", line 31, in read_yaml
    raise ValueError("yaml file is empty")
ValueError: yaml file is empty
[2025-01-01 15:21:34,388: INFO: main: >>>>>>stage DATA INGESTION STAGE started<<<<<<]
[2025-01-01 15:21:34,398: INFO: common: yaml file : config\config.yaml loaded successfully]
[2025-01-01 15:21:34,399: ERROR: main: name 'params_filepath' is not defined]
Traceback (most recent call last):
  File "C:\Users\sunny\Desktop\MLOps\Data_science_project1\main.py", line 8, in <module>
    obj.initiate_data_ingestion()
  File "C:\Users\sunny\Desktop\MLOps\Data_science_project1\src\datascience\pipeline\data_ingestion_pipeline.py", line 12, in initiate_data_ingestion
    config=ConfigurationManager()
           ^^^^^^^^^^^^^^^^^^^^^^
  File "C:\Users\sunny\Desktop\MLOps\Data_science_project1\src\datascience\config\configuration.py", line 12, in __init__
    self.params=read_yaml(params_filepath)
                          ^^^^^^^^^^^^^^^
NameError: name 'params_filepath' is not defined
[2025-01-01 15:22:46,214: INFO: main: >>>>>>stage DATA INGESTION STAGE started<<<<<<]
[2025-01-01 15:22:46,216: INFO: common: yaml file : config\config.yaml loaded successfully]
[2025-01-01 15:22:46,217: ERROR: main: [Errno 2] No such file or directory: 'parmas.yaml']
Traceback (most recent call last):
  File "C:\Users\sunny\Desktop\MLOps\Data_science_project1\main.py", line 8, in <module>
    obj.initiate_data_ingestion()
  File "C:\Users\sunny\Desktop\MLOps\Data_science_project1\src\datascience\pipeline\data_ingestion_pipeline.py", line 12, in initiate_data_ingestion
    config=ConfigurationManager()
           ^^^^^^^^^^^^^^^^^^^^^^
  File "C:\Users\sunny\Desktop\MLOps\Data_science_project1\src\datascience\config\configuration.py", line 12, in __init__
    self.params=read_yaml(params_filepath)
                ^^^^^^^^^^^^^^^^^^^^^^^^^^
  File "C:\Users\sunny\AppData\Local\Programs\Python\Python311\Lib\site-packages\ensure\main.py", line 872, in __call__
    return_val = self.f(*args, **kwargs)
                 ^^^^^^^^^^^^^^^^^^^^^^^
  File "C:\Users\sunny\Desktop\MLOps\Data_science_project1\src\datascience\utils\common.py", line 33, in read_yaml
    raise e
  File "C:\Users\sunny\Desktop\MLOps\Data_science_project1\src\datascience\utils\common.py", line 26, in read_yaml
    with open(path_to_yaml) as yaml_file:
         ^^^^^^^^^^^^^^^^^^
FileNotFoundError: [Errno 2] No such file or directory: 'parmas.yaml'
[2025-01-01 15:25:51,826: INFO: main: >>>>>>stage DATA INGESTION STAGE started<<<<<<]
[2025-01-01 15:25:51,834: INFO: common: yaml file : config\config.yaml loaded successfully]
[2025-01-01 15:25:51,835: ERROR: main: [Errno 2] No such file or directory: 'parmas.yaml']
Traceback (most recent call last):
  File "C:\Users\sunny\Desktop\MLOps\Data_science_project1\main.py", line 8, in <module>
    obj.initiate_data_ingestion()
  File "C:\Users\sunny\Desktop\MLOps\Data_science_project1\src\datascience\pipeline\data_ingestion_pipeline.py", line 12, in initiate_data_ingestion
    config=ConfigurationManager()
           ^^^^^^^^^^^^^^^^^^^^^^
  File "C:\Users\sunny\Desktop\MLOps\Data_science_project1\src\datascience\config\configuration.py", line 12, in __init__
    self.params=read_yaml(params_filepath)
                ^^^^^^^^^^^^^^^^^^^^^^^^^^
  File "C:\Users\sunny\AppData\Local\Programs\Python\Python311\Lib\site-packages\ensure\main.py", line 872, in __call__
    return_val = self.f(*args, **kwargs)
                 ^^^^^^^^^^^^^^^^^^^^^^^
  File "C:\Users\sunny\Desktop\MLOps\Data_science_project1\src\datascience\utils\common.py", line 33, in read_yaml
    raise e
  File "C:\Users\sunny\Desktop\MLOps\Data_science_project1\src\datascience\utils\common.py", line 26, in read_yaml
    with open(path_to_yaml) as yaml_file:
         ^^^^^^^^^^^^^^^^^^
FileNotFoundError: [Errno 2] No such file or directory: 'parmas.yaml'
[2025-01-01 15:29:03,190: INFO: main: >>>>>>stage DATA INGESTION STAGE started<<<<<<]
[2025-01-01 15:29:03,203: INFO: common: yaml file : config\config.yaml loaded successfully]
[2025-01-01 15:29:03,205: INFO: common: yaml file : params.yaml loaded successfully]
[2025-01-01 15:29:03,207: INFO: common: yaml file : schema.yaml loaded successfully]
[2025-01-01 15:29:03,208: INFO: common: created directory at artifacts]
[2025-01-01 15:29:03,208: INFO: common: created directory at artifacts/data_ingestion]
[2025-01-01 15:29:03,679: ERROR: main: HTTP Error 404: Not Found]
Traceback (most recent call last):
  File "C:\Users\sunny\Desktop\MLOps\Data_science_project1\main.py", line 8, in <module>
    obj.initiate_data_ingestion()
  File "C:\Users\sunny\Desktop\MLOps\Data_science_project1\src\datascience\pipeline\data_ingestion_pipeline.py", line 15, in initiate_data_ingestion
    data_ingestion.download_file()
  File "C:\Users\sunny\Desktop\MLOps\Data_science_project1\src\datascience\components\data_ingestion.py", line 14, in download_file
    filename,headers=request.urlretrieve(
                     ^^^^^^^^^^^^^^^^^^^^
  File "C:\Users\sunny\AppData\Local\Programs\Python\Python311\Lib\urllib\request.py", line 241, in urlretrieve
    with contextlib.closing(urlopen(url, data)) as fp:
                            ^^^^^^^^^^^^^^^^^^
  File "C:\Users\sunny\AppData\Local\Programs\Python\Python311\Lib\urllib\request.py", line 216, in urlopen
    return opener.open(url, data, timeout)
           ^^^^^^^^^^^^^^^^^^^^^^^^^^^^^^^
  File "C:\Users\sunny\AppData\Local\Programs\Python\Python311\Lib\urllib\request.py", line 525, in open
    response = meth(req, response)
               ^^^^^^^^^^^^^^^^^^^
  File "C:\Users\sunny\AppData\Local\Programs\Python\Python311\Lib\urllib\request.py", line 634, in http_response
    response = self.parent.error(
               ^^^^^^^^^^^^^^^^^^
  File "C:\Users\sunny\AppData\Local\Programs\Python\Python311\Lib\urllib\request.py", line 563, in error
    return self._call_chain(*args)
           ^^^^^^^^^^^^^^^^^^^^^^^
  File "C:\Users\sunny\AppData\Local\Programs\Python\Python311\Lib\urllib\request.py", line 496, in _call_chain
    result = func(*args)
             ^^^^^^^^^^^
  File "C:\Users\sunny\AppData\Local\Programs\Python\Python311\Lib\urllib\request.py", line 643, in http_error_default
    raise HTTPError(req.full_url, code, msg, hdrs, fp)
urllib.error.HTTPError: HTTP Error 404: Not Found
[2025-01-01 15:40:21,199: INFO: main: >>>>>>stage DATA INGESTION STAGE started<<<<<<]
[2025-01-01 15:40:21,206: INFO: common: yaml file : config\config.yaml loaded successfully]
[2025-01-01 15:40:21,207: INFO: common: yaml file : params.yaml loaded successfully]
[2025-01-01 15:40:21,209: INFO: common: yaml file : schema.yaml loaded successfully]
[2025-01-01 15:40:21,210: INFO: common: created directory at artifacts]
[2025-01-01 15:40:21,210: INFO: common: created directory at artifacts/data_ingestion]
[2025-01-01 15:40:21,906: INFO: data_ingestion: artifacts/data_ingestion/data.zip downloaded with following info: 
Server: GitHub.com
Date: Wed, 01 Jan 2025 10:10:19 GMT
Content-Type: text/html; charset=utf-8
Vary: X-PJAX, X-PJAX-Container, Turbo-Visit, Turbo-Frame, Accept-Encoding, Accept, X-Requested-With
ETag: W/"d727c733cc8f8eee6a6b83fdfa7be3dc"
Cache-Control: max-age=0, private, must-revalidate
Strict-Transport-Security: max-age=31536000; includeSubdomains; preload
X-Frame-Options: deny
X-Content-Type-Options: nosniff
X-XSS-Protection: 0
Referrer-Policy: no-referrer-when-downgrade
Content-Security-Policy: default-src 'none'; base-uri 'self'; child-src github.com/assets-cdn/worker/ github.com/webpack/ github.com/assets/ gist.github.com/assets-cdn/worker/; connect-src 'self' uploads.github.com www.githubstatus.com collector.github.com raw.githubusercontent.com api.github.com github-cloud.s3.amazonaws.com github-production-repository-file-5c1aeb.s3.amazonaws.com github-production-upload-manifest-file-7fdce7.s3.amazonaws.com github-production-user-asset-6210df.s3.amazonaws.com *.rel.tunnels.api.visualstudio.com wss://*.rel.tunnels.api.visualstudio.com objects-origin.githubusercontent.com copilot-proxy.githubusercontent.com proxy.individual.githubcopilot.com proxy.business.githubcopilot.com proxy.enterprise.githubcopilot.com *.actions.githubusercontent.com wss://*.actions.githubusercontent.com productionresultssa0.blob.core.windows.net/ productionresultssa1.blob.core.windows.net/ productionresultssa2.blob.core.windows.net/ productionresultssa3.blob.core.windows.net/ productionresultssa4.blob.core.windows.net/ productionresultssa5.blob.core.windows.net/ productionresultssa6.blob.core.windows.net/ productionresultssa7.blob.core.windows.net/ productionresultssa8.blob.core.windows.net/ productionresultssa9.blob.core.windows.net/ productionresultssa10.blob.core.windows.net/ productionresultssa11.blob.core.windows.net/ productionresultssa12.blob.core.windows.net/ productionresultssa13.blob.core.windows.net/ productionresultssa14.blob.core.windows.net/ productionresultssa15.blob.core.windows.net/ productionresultssa16.blob.core.windows.net/ productionresultssa17.blob.core.windows.net/ productionresultssa18.blob.core.windows.net/ productionresultssa19.blob.core.windows.net/ github-production-repository-image-32fea6.s3.amazonaws.com github-production-release-asset-2e65be.s3.amazonaws.com insights.github.com wss://alive.github.com api.githubcopilot.com api.individual.githubcopilot.com api.business.githubcopilot.com api.enterprise.githubcopilot.com; font-src github.githubassets.com; form-action 'self' github.com gist.github.com copilot-workspace.githubnext.com objects-origin.githubusercontent.com; frame-ancestors 'none'; frame-src viewscreen.githubusercontent.com notebooks.githubusercontent.com; img-src 'self' data: blob: github.githubassets.com media.githubusercontent.com camo.githubusercontent.com identicons.github.com avatars.githubusercontent.com private-avatars.githubusercontent.com github-cloud.s3.amazonaws.com objects.githubusercontent.com secured-user-images.githubusercontent.com/ user-images.githubusercontent.com/ private-user-images.githubusercontent.com opengraph.githubassets.com github-production-user-asset-6210df.s3.amazonaws.com customer-stories-feed.github.com spotlights-feed.github.com objects-origin.githubusercontent.com *.githubusercontent.com; manifest-src 'self'; media-src github.com user-images.githubusercontent.com/ secured-user-images.githubusercontent.com/ private-user-images.githubusercontent.com github-production-user-asset-6210df.s3.amazonaws.com gist.github.com; script-src github.githubassets.com; style-src 'unsafe-inline' github.githubassets.com; upgrade-insecure-requests; worker-src github.com/assets-cdn/worker/ github.com/webpack/ github.com/assets/ gist.github.com/assets-cdn/worker/
Set-Cookie: _gh_sess=aEmqUNym5wMH8qQrZC14rzQxmqx9iQcuSGaGTKR3qCQSGs5V4y0pVoP20vrKKOktphy6fZRReJwTbwR02R%2Bpt21IjK%2Bq2vQixtbn2IjHAssMsWHpnHx2LgcxIDQjSk6QahilPS0QsNuoXCb673AreljEVdn%2F31ZxRiO8G8%2FAQrfeLEPt8bZkP5MHtxQ4HrhKFFpeWtKBRmfdCygOAYn4Lo043uNBtVDi6WM2ySmp7edOPh8y%2BgoorfCgVeRjnQeAsCSG9e1WZqw7FJGaNp0whA%3D%3D--Jf8Dy6I%2FV5zH9D4Y--KFdCeNOryUPvwk2FRU1NOQ%3D%3D; Path=/; HttpOnly; Secure; SameSite=Lax
Set-Cookie: _octo=GH1.1.1551789185.1735726218; Path=/; Domain=github.com; Expires=Thu, 01 Jan 2026 10:10:18 GMT; Secure; SameSite=Lax
Set-Cookie: logged_in=no; Path=/; Domain=github.com; Expires=Thu, 01 Jan 2026 10:10:18 GMT; HttpOnly; Secure; SameSite=Lax
Accept-Ranges: bytes
Transfer-Encoding: chunked
X-GitHub-Request-Id: 0A13:09F1:3CC4D7E:496AB92:6775148A
connection: close

]
[2025-01-01 15:40:21,939: ERROR: main: File is not a zip file]
Traceback (most recent call last):
  File "C:\Users\sunny\Desktop\MLOps\Data_science_project1\main.py", line 8, in <module>
    obj.initiate_data_ingestion()
  File "C:\Users\sunny\Desktop\MLOps\Data_science_project1\src\datascience\pipeline\data_ingestion_pipeline.py", line 16, in initiate_data_ingestion
    data_ingestion.extract_zip_file()
  File "C:\Users\sunny\Desktop\MLOps\Data_science_project1\src\datascience\components\data_ingestion.py", line 25, in extract_zip_file
    with zipfile.ZipFile(self.config.local_data_file,'r') as zip_ref:
         ^^^^^^^^^^^^^^^^^^^^^^^^^^^^^^^^^^^^^^^^^^^^^^^^
  File "C:\Users\sunny\AppData\Local\Programs\Python\Python311\Lib\zipfile.py", line 1299, in __init__
    self._RealGetContents()
  File "C:\Users\sunny\AppData\Local\Programs\Python\Python311\Lib\zipfile.py", line 1366, in _RealGetContents
    raise BadZipFile("File is not a zip file")
zipfile.BadZipFile: File is not a zip file
[2025-01-01 15:42:46,761: INFO: main: >>>>>>stage DATA INGESTION STAGE started<<<<<<]
[2025-01-01 15:42:46,765: INFO: common: yaml file : config\config.yaml loaded successfully]
[2025-01-01 15:42:46,766: INFO: common: yaml file : params.yaml loaded successfully]
[2025-01-01 15:42:46,768: INFO: common: yaml file : schema.yaml loaded successfully]
[2025-01-01 15:42:46,769: INFO: common: created directory at artifacts]
[2025-01-01 15:42:46,770: INFO: common: created directory at artifacts/data_ingestion]
[2025-01-01 15:42:46,770: INFO: data_ingestion: File already exist]
[2025-01-01 15:42:46,771: ERROR: main: File is not a zip file]
Traceback (most recent call last):
  File "C:\Users\sunny\Desktop\MLOps\Data_science_project1\main.py", line 8, in <module>
    obj.initiate_data_ingestion()
  File "C:\Users\sunny\Desktop\MLOps\Data_science_project1\src\datascience\pipeline\data_ingestion_pipeline.py", line 16, in initiate_data_ingestion
    data_ingestion.extract_zip_file()
  File "C:\Users\sunny\Desktop\MLOps\Data_science_project1\src\datascience\components\data_ingestion.py", line 25, in extract_zip_file
    with zipfile.ZipFile(self.config.local_data_file,'r') as zip_ref:
         ^^^^^^^^^^^^^^^^^^^^^^^^^^^^^^^^^^^^^^^^^^^^^^^^
  File "C:\Users\sunny\AppData\Local\Programs\Python\Python311\Lib\zipfile.py", line 1299, in __init__
    self._RealGetContents()
  File "C:\Users\sunny\AppData\Local\Programs\Python\Python311\Lib\zipfile.py", line 1366, in _RealGetContents
    raise BadZipFile("File is not a zip file")
zipfile.BadZipFile: File is not a zip file
[2025-01-01 15:44:29,277: INFO: main: >>>>>>stage DATA INGESTION STAGE started<<<<<<]
[2025-01-01 15:44:29,282: INFO: common: yaml file : config\config.yaml loaded successfully]
[2025-01-01 15:44:29,283: INFO: common: yaml file : params.yaml loaded successfully]
[2025-01-01 15:44:29,285: INFO: common: yaml file : schema.yaml loaded successfully]
[2025-01-01 15:44:29,286: INFO: common: created directory at artifacts]
[2025-01-01 15:44:29,287: INFO: common: created directory at artifacts/data_ingestion]
[2025-01-01 15:44:29,287: INFO: data_ingestion: File already exist]
[2025-01-01 15:44:29,288: ERROR: main: File is not a zip file]
Traceback (most recent call last):
  File "C:\Users\sunny\Desktop\MLOps\Data_science_project1\main.py", line 8, in <module>
    obj.initiate_data_ingestion()
  File "C:\Users\sunny\Desktop\MLOps\Data_science_project1\src\datascience\pipeline\data_ingestion_pipeline.py", line 16, in initiate_data_ingestion
    data_ingestion.extract_zip_file()
  File "C:\Users\sunny\Desktop\MLOps\Data_science_project1\src\datascience\components\data_ingestion.py", line 25, in extract_zip_file
    with zipfile.ZipFile(self.config.local_data_file,'r') as zip_ref:
         ^^^^^^^^^^^^^^^^^^^^^^^^^^^^^^^^^^^^^^^^^^^^^^^^
  File "C:\Users\sunny\AppData\Local\Programs\Python\Python311\Lib\zipfile.py", line 1299, in __init__
    self._RealGetContents()
  File "C:\Users\sunny\AppData\Local\Programs\Python\Python311\Lib\zipfile.py", line 1366, in _RealGetContents
    raise BadZipFile("File is not a zip file")
zipfile.BadZipFile: File is not a zip file
[2025-01-01 16:04:58,833: INFO: main: >>>>>>stage DATA INGESTION STAGE started<<<<<<]
[2025-01-01 16:04:58,840: INFO: common: yaml file : config\config.yaml loaded successfully]
[2025-01-01 16:04:58,841: INFO: common: yaml file : params.yaml loaded successfully]
[2025-01-01 16:04:58,844: INFO: common: yaml file : schema.yaml loaded successfully]
[2025-01-01 16:04:58,844: INFO: common: created directory at artifacts]
[2025-01-01 16:04:58,846: INFO: common: created directory at artifacts/data_ingestion]
[2025-01-01 16:04:58,846: INFO: data_ingestion: File already exist]
[2025-01-01 16:04:58,847: ERROR: main: File is not a zip file]
Traceback (most recent call last):
  File "C:\Users\sunny\Desktop\MLOps\Data_science_project1\main.py", line 8, in <module>
    obj.initiate_data_ingestion()
  File "C:\Users\sunny\Desktop\MLOps\Data_science_project1\src\datascience\pipeline\data_ingestion_pipeline.py", line 16, in initiate_data_ingestion
    data_ingestion.extract_zip_file()
  File "C:\Users\sunny\Desktop\MLOps\Data_science_project1\src\datascience\components\data_ingestion.py", line 25, in extract_zip_file
    with zipfile.ZipFile(self.config.local_data_file,'r') as zip_ref:
         ^^^^^^^^^^^^^^^^^^^^^^^^^^^^^^^^^^^^^^^^^^^^^^^^
  File "C:\Users\sunny\AppData\Local\Programs\Python\Python311\Lib\zipfile.py", line 1299, in __init__
    self._RealGetContents()
  File "C:\Users\sunny\AppData\Local\Programs\Python\Python311\Lib\zipfile.py", line 1366, in _RealGetContents
    raise BadZipFile("File is not a zip file")
zipfile.BadZipFile: File is not a zip file
[2025-01-01 16:05:38,964: INFO: main: >>>>>>stage DATA INGESTION STAGE started<<<<<<]
[2025-01-01 16:05:38,970: INFO: common: yaml file : config\config.yaml loaded successfully]
[2025-01-01 16:05:38,971: INFO: common: yaml file : params.yaml loaded successfully]
[2025-01-01 16:05:38,973: INFO: common: yaml file : schema.yaml loaded successfully]
[2025-01-01 16:05:38,974: INFO: common: created directory at artifacts]
[2025-01-01 16:05:38,975: INFO: common: created directory at artifacts/data_ingestion]
[2025-01-01 16:05:39,739: INFO: data_ingestion: artifacts/data_ingestion/data.zip downloaded with following info: 
Connection: close
Content-Length: 23329
Cache-Control: max-age=300
Content-Security-Policy: default-src 'none'; style-src 'unsafe-inline'; sandbox
Content-Type: application/zip
ETag: "c69888a4ae59bc5a893392785a938ccd4937981c06ba8a9d6a21aa52b4ab5b6e"
Strict-Transport-Security: max-age=31536000
X-Content-Type-Options: nosniff
X-Frame-Options: deny
X-XSS-Protection: 1; mode=block
X-GitHub-Request-Id: 4707:21E82C:71886F:A8F5B3:67751A78
Accept-Ranges: bytes
Date: Wed, 01 Jan 2025 10:35:36 GMT
Via: 1.1 varnish
X-Served-By: cache-del21751-DEL
X-Cache: MISS
X-Cache-Hits: 0
X-Timer: S1735727737.514172,VS0,VE298
Vary: Authorization,Accept-Encoding,Origin
Access-Control-Allow-Origin: *
Cross-Origin-Resource-Policy: cross-origin
X-Fastly-Request-ID: bf654c3a62d3928d8b301fddf0b9eccd50439238
Expires: Wed, 01 Jan 2025 10:40:36 GMT
Source-Age: 0

]
[2025-01-01 16:05:39,746: INFO: main: >>>>>stage DATA INGESTION STAGE completed <<<<<<<]
[2025-01-01 16:55:37,484: INFO: main: >>>>>>stage DATA INGESTION STAGE started<<<<<<]
[2025-01-01 16:55:37,491: INFO: common: yaml file : config\config.yaml loaded successfully]
[2025-01-01 16:55:37,494: INFO: common: yaml file : params.yaml loaded successfully]
[2025-01-01 16:55:37,496: INFO: common: yaml file : schema.yaml loaded successfully]
[2025-01-01 16:55:37,500: INFO: common: created directory at artifacts]
[2025-01-01 16:55:37,501: INFO: common: created directory at artifacts/data_ingestion]
[2025-01-01 16:55:37,501: INFO: data_ingestion: File already exist]
[2025-01-01 16:55:37,504: INFO: main: >>>>>stage DATA INGESTION STAGE completed <<<<<<<]
[2025-01-01 16:55:37,504: INFO: main: >>>>>>stage DATA VALIDATION STAGE started<<<<<<]
[2025-01-01 16:55:37,506: INFO: common: yaml file : config\config.yaml loaded successfully]
[2025-01-01 16:55:37,506: INFO: common: yaml file : params.yaml loaded successfully]
[2025-01-01 16:55:37,508: INFO: common: yaml file : schema.yaml loaded successfully]
[2025-01-01 16:55:37,509: INFO: common: created directory at artifacts]
[2025-01-01 16:55:37,509: INFO: common: created directory at artifacts/data_validation]
[2025-01-01 16:55:37,517: ERROR: main: "'ConfigBox' object has no attribute 'unzip_dir'"]
Traceback (most recent call last):
  File "box\\box.py", line 593, in box.box.Box.__getitem__
KeyError: 'unzip_dir'

The above exception was the direct cause of the following exception:

Traceback (most recent call last):
  File "box\\box.py", line 632, in box.box.Box.__getattr__
  File "box\\box.py", line 620, in box.box.Box.__getitem__
box.exceptions.BoxKeyError: "'unzip_dir'"

During handling of the above exception, another exception occurred:

Traceback (most recent call last):
  File "box\\box.py", line 634, in box.box.Box.__getattr__
AttributeError: 'ConfigBox' object has no attribute 'unzip_dir'

The above exception was the direct cause of the following exception:

Traceback (most recent call last):
  File "box\\config_box.py", line 29, in box.config_box.ConfigBox.__getattr__
  File "box\\box.py", line 648, in box.box.Box.__getattr__
box.exceptions.BoxKeyError: "'ConfigBox' object has no attribute 'unzip_dir'"

During handling of the above exception, another exception occurred:

Traceback (most recent call last):
  File "box\\box.py", line 593, in box.box.Box.__getitem__
KeyError: 'unzip_dir'

The above exception was the direct cause of the following exception:

Traceback (most recent call last):
  File "box\\box.py", line 632, in box.box.Box.__getattr__
  File "box\\box.py", line 620, in box.box.Box.__getitem__
box.exceptions.BoxKeyError: "'unzip_dir'"

During handling of the above exception, another exception occurred:

Traceback (most recent call last):
  File "box\\box.py", line 634, in box.box.Box.__getattr__
AttributeError: 'ConfigBox' object has no attribute 'unzip_dir'

The above exception was the direct cause of the following exception:

Traceback (most recent call last):
  File "C:\Users\sunny\Desktop\MLOps\Data_science_project1\main.py", line 19, in <module>
    obj.initiate_data_validation()
  File "C:\Users\sunny\Desktop\MLOps\Data_science_project1\src\datascience\pipeline\data_validation_pipeline.py", line 13, in initiate_data_validation
    data_validation_config=config.get_data_validation_config()
                           ^^^^^^^^^^^^^^^^^^^^^^^^^^^^^^^^^^^
  File "C:\Users\sunny\Desktop\MLOps\Data_science_project1\src\datascience\config\configuration.py", line 40, in get_data_validation_config
    unzip_data_dir=config.unzip_dir,
                   ^^^^^^^^^^^^^^^^
  File "box\\config_box.py", line 31, in box.config_box.ConfigBox.__getattr__
  File "box\\box.py", line 648, in box.box.Box.__getattr__
box.exceptions.BoxKeyError: "'ConfigBox' object has no attribute 'unzip_dir'"
[2025-01-01 16:58:20,912: INFO: main: >>>>>>stage DATA INGESTION STAGE started<<<<<<]
[2025-01-01 16:58:20,928: INFO: common: yaml file : config\config.yaml loaded successfully]
[2025-01-01 16:58:20,930: INFO: common: yaml file : params.yaml loaded successfully]
[2025-01-01 16:58:20,932: INFO: common: yaml file : schema.yaml loaded successfully]
[2025-01-01 16:58:20,933: INFO: common: created directory at artifacts]
[2025-01-01 16:58:20,934: INFO: common: created directory at artifacts/data_ingestion]
[2025-01-01 16:58:20,935: INFO: data_ingestion: File already exist]
[2025-01-01 16:58:20,937: INFO: main: >>>>>stage DATA INGESTION STAGE completed <<<<<<<]
[2025-01-01 16:58:20,938: INFO: main: >>>>>>stage DATA VALIDATION STAGE started<<<<<<]
[2025-01-01 16:58:20,939: INFO: common: yaml file : config\config.yaml loaded successfully]
[2025-01-01 16:58:20,940: INFO: common: yaml file : params.yaml loaded successfully]
[2025-01-01 16:58:20,944: INFO: common: yaml file : schema.yaml loaded successfully]
[2025-01-01 16:58:20,945: INFO: common: created directory at artifacts]
[2025-01-01 16:58:20,946: INFO: common: created directory at artifacts/data_validation]
[2025-01-01 16:58:20,946: ERROR: main: name 'pd' is not defined]
Traceback (most recent call last):
  File "C:\Users\sunny\Desktop\MLOps\Data_science_project1\main.py", line 19, in <module>
    obj.initiate_data_validation()
  File "C:\Users\sunny\Desktop\MLOps\Data_science_project1\src\datascience\pipeline\data_validation_pipeline.py", line 15, in initiate_data_validation
    data_validation.validate_all_columns()
  File "C:\Users\sunny\Desktop\MLOps\Data_science_project1\src\datascience\components\data_validation.py", line 31, in validate_all_columns
    raise e
  File "C:\Users\sunny\Desktop\MLOps\Data_science_project1\src\datascience\components\data_validation.py", line 15, in validate_all_columns
    data=pd.read_csv(self.config.unzip_data_dir)
         ^^
NameError: name 'pd' is not defined
[2025-01-01 16:59:03,283: INFO: main: >>>>>>stage DATA INGESTION STAGE started<<<<<<]
[2025-01-01 16:59:03,290: INFO: common: yaml file : config\config.yaml loaded successfully]
[2025-01-01 16:59:03,292: INFO: common: yaml file : params.yaml loaded successfully]
[2025-01-01 16:59:03,294: INFO: common: yaml file : schema.yaml loaded successfully]
[2025-01-01 16:59:03,295: INFO: common: created directory at artifacts]
[2025-01-01 16:59:03,296: INFO: common: created directory at artifacts/data_ingestion]
[2025-01-01 16:59:03,297: INFO: data_ingestion: File already exist]
[2025-01-01 16:59:03,300: INFO: main: >>>>>stage DATA INGESTION STAGE completed <<<<<<<]
[2025-01-01 16:59:03,301: INFO: main: >>>>>>stage DATA VALIDATION STAGE started<<<<<<]
[2025-01-01 16:59:03,302: INFO: common: yaml file : config\config.yaml loaded successfully]
[2025-01-01 16:59:03,306: INFO: common: yaml file : params.yaml loaded successfully]
[2025-01-01 16:59:03,308: INFO: common: yaml file : schema.yaml loaded successfully]
[2025-01-01 16:59:03,309: INFO: common: created directory at artifacts]
[2025-01-01 16:59:03,309: INFO: common: created directory at artifacts/data_validation]
[2025-01-01 16:59:03,329: INFO: main: >>>>>stage DATA VALIDATION STAGE completed <<<<<<<]
[2025-01-01 20:42:12,334: INFO: main: >>>>>>stage DATA INGESTION STAGE started<<<<<<]
[2025-01-01 20:42:12,334: INFO: common: yaml file : config\config.yaml loaded successfully]
[2025-01-01 20:42:12,334: INFO: common: yaml file : params.yaml loaded successfully]
[2025-01-01 20:42:12,350: INFO: common: yaml file : schema.yaml loaded successfully]
[2025-01-01 20:42:12,350: INFO: common: created directory at artifacts]
[2025-01-01 20:42:12,350: INFO: common: created directory at artifacts/data_ingestion]
[2025-01-01 20:42:12,353: INFO: data_ingestion: File already exist]
[2025-01-01 20:42:12,357: INFO: main: >>>>>stage DATA INGESTION STAGE completed <<<<<<<]
[2025-01-01 20:42:12,365: INFO: main: >>>>>>stage DATA VALIDATION STAGE started<<<<<<]
[2025-01-01 20:42:12,368: INFO: common: yaml file : config\config.yaml loaded successfully]
[2025-01-01 20:42:12,369: INFO: common: yaml file : params.yaml loaded successfully]
[2025-01-01 20:42:12,371: INFO: common: yaml file : schema.yaml loaded successfully]
[2025-01-01 20:42:12,372: INFO: common: created directory at artifacts]
[2025-01-01 20:42:12,386: INFO: common: created directory at artifacts/data_validation]
[2025-01-01 20:42:12,405: INFO: main: >>>>>stage DATA VALIDATION STAGE completed <<<<<<<]
[2025-01-01 20:42:12,418: INFO: main: >>>>>>stage DATA TRANSFORMATION STAGE started<<<<<<]
[2025-01-01 20:42:12,420: INFO: common: yaml file : config\config.yaml loaded successfully]
[2025-01-01 20:42:12,421: INFO: common: yaml file : params.yaml loaded successfully]
[2025-01-01 20:42:12,432: INFO: common: yaml file : schema.yaml loaded successfully]
[2025-01-01 20:42:12,433: INFO: common: created directory at artifacts]
[2025-01-01 20:42:12,434: INFO: common: created directory at artifacts/data_transformation]
[2025-01-01 20:42:12,467: INFO: data_transformation: Splitted the data into train and test]
[2025-01-01 20:42:12,468: INFO: data_transformation: (1199, 12)]
[2025-01-01 20:42:12,468: INFO: data_transformation: (400, 12)]
[2025-01-01 20:42:12,470: INFO: main: >>>>>stage DATA TRANSFORMATION STAGE completed <<<<<<<]
[2025-01-01 21:19:24,478: INFO: main: >>>>>>stage DATA INGESTION STAGE started<<<<<<]
[2025-01-01 21:19:24,478: INFO: common: yaml file : config\config.yaml loaded successfully]
[2025-01-01 21:19:24,478: INFO: common: yaml file : params.yaml loaded successfully]
[2025-01-01 21:19:24,478: INFO: common: yaml file : schema.yaml loaded successfully]
[2025-01-01 21:19:24,478: INFO: common: created directory at artifacts]
[2025-01-01 21:19:24,478: INFO: common: created directory at artifacts/data_ingestion]
[2025-01-01 21:19:24,488: INFO: data_ingestion: File already exist]
[2025-01-01 21:19:24,490: INFO: main: >>>>>stage DATA INGESTION STAGE completed <<<<<<<]
[2025-01-01 21:19:24,495: INFO: main: >>>>>>stage DATA VALIDATION STAGE started<<<<<<]
[2025-01-01 21:19:24,498: INFO: common: yaml file : config\config.yaml loaded successfully]
[2025-01-01 21:19:24,499: INFO: common: yaml file : params.yaml loaded successfully]
[2025-01-01 21:19:24,501: INFO: common: yaml file : schema.yaml loaded successfully]
[2025-01-01 21:19:24,501: INFO: common: created directory at artifacts]
[2025-01-01 21:19:24,502: INFO: common: created directory at artifacts/data_validation]
[2025-01-01 21:19:24,512: INFO: main: >>>>>stage DATA VALIDATION STAGE completed <<<<<<<]
[2025-01-01 21:19:24,517: INFO: main: >>>>>>stage DATA TRANSFORMATION STAGE started<<<<<<]
[2025-01-01 21:19:24,519: INFO: common: yaml file : config\config.yaml loaded successfully]
[2025-01-01 21:19:24,520: INFO: common: yaml file : params.yaml loaded successfully]
[2025-01-01 21:19:24,522: INFO: common: yaml file : schema.yaml loaded successfully]
[2025-01-01 21:19:24,522: INFO: common: created directory at artifacts]
[2025-01-01 21:19:24,523: INFO: common: created directory at artifacts/data_transformation]
[2025-01-01 21:19:24,542: INFO: data_transformation: Splitted the data into train and test]
[2025-01-01 21:19:24,543: INFO: data_transformation: (1199, 12)]
[2025-01-01 21:19:24,544: INFO: data_transformation: (400, 12)]
[2025-01-01 21:19:24,544: INFO: main: >>>>>stage DATA TRANSFORMATION STAGE completed <<<<<<<]
[2025-01-01 21:19:24,545: INFO: main: >>>>>>stage MODEL TRAINING STAGE started<<<<<<]
[2025-01-01 21:19:24,555: INFO: common: yaml file : config\config.yaml loaded successfully]
[2025-01-01 21:19:24,555: INFO: common: yaml file : params.yaml loaded successfully]
[2025-01-01 21:19:24,557: INFO: common: yaml file : schema.yaml loaded successfully]
[2025-01-01 21:19:24,558: INFO: common: created directory at artifacts]
[2025-01-01 21:19:24,558: INFO: common: created directory at artifacts/model_trainer]
[2025-01-01 21:19:24,568: ERROR: main: "'ConfigBox' object has no attribute 'alpha'"]
Traceback (most recent call last):
  File "box\\box.py", line 593, in box.box.Box.__getitem__
KeyError: 'alpha'

The above exception was the direct cause of the following exception:

Traceback (most recent call last):
  File "box\\box.py", line 632, in box.box.Box.__getattr__
  File "box\\box.py", line 620, in box.box.Box.__getitem__
box.exceptions.BoxKeyError: "'alpha'"

During handling of the above exception, another exception occurred:

Traceback (most recent call last):
  File "box\\box.py", line 634, in box.box.Box.__getattr__
AttributeError: 'ConfigBox' object has no attribute 'alpha'

The above exception was the direct cause of the following exception:

Traceback (most recent call last):
  File "box\\config_box.py", line 29, in box.config_box.ConfigBox.__getattr__
  File "box\\box.py", line 648, in box.box.Box.__getattr__
box.exceptions.BoxKeyError: "'ConfigBox' object has no attribute 'alpha'"

During handling of the above exception, another exception occurred:

Traceback (most recent call last):
  File "box\\box.py", line 593, in box.box.Box.__getitem__
KeyError: 'alpha'

The above exception was the direct cause of the following exception:

Traceback (most recent call last):
  File "box\\box.py", line 632, in box.box.Box.__getattr__
  File "box\\box.py", line 620, in box.box.Box.__getitem__
box.exceptions.BoxKeyError: "'alpha'"

During handling of the above exception, another exception occurred:

Traceback (most recent call last):
  File "box\\box.py", line 634, in box.box.Box.__getattr__
AttributeError: 'ConfigBox' object has no attribute 'alpha'

The above exception was the direct cause of the following exception:

Traceback (most recent call last):
  File "C:\Users\sunny\Desktop\MLOps\Data_science_project1\main.py", line 41, in <module>
    obj.initiate_model_trainer()
  File "C:\Users\sunny\Desktop\MLOps\Data_science_project1\src\datascience\pipeline\model_trainer_pipeline.py", line 13, in initiate_model_trainer
    model_trainer_config=config.get_model_trainer_config()
                         ^^^^^^^^^^^^^^^^^^^^^^^^^^^^^^^^^
  File "C:\Users\sunny\Desktop\MLOps\Data_science_project1\src\datascience\config\configuration.py", line 85, in get_model_trainer_config
    alpha=config.alpha,
          ^^^^^^^^^^^^
  File "box\\config_box.py", line 31, in box.config_box.ConfigBox.__getattr__
  File "box\\box.py", line 648, in box.box.Box.__getattr__
box.exceptions.BoxKeyError: "'ConfigBox' object has no attribute 'alpha'"
[2025-01-01 21:22:10,564: INFO: main: >>>>>>stage DATA INGESTION STAGE started<<<<<<]
[2025-01-01 21:22:10,577: INFO: common: yaml file : config\config.yaml loaded successfully]
[2025-01-01 21:22:10,577: INFO: common: yaml file : params.yaml loaded successfully]
[2025-01-01 21:22:10,580: INFO: common: yaml file : schema.yaml loaded successfully]
[2025-01-01 21:22:10,580: INFO: common: created directory at artifacts]
[2025-01-01 21:22:10,580: INFO: common: created directory at artifacts/data_ingestion]
[2025-01-01 21:22:10,582: INFO: data_ingestion: File already exist]
[2025-01-01 21:22:10,584: INFO: main: >>>>>stage DATA INGESTION STAGE completed <<<<<<<]
[2025-01-01 21:22:10,588: INFO: main: >>>>>>stage DATA VALIDATION STAGE started<<<<<<]
[2025-01-01 21:22:10,591: INFO: common: yaml file : config\config.yaml loaded successfully]
[2025-01-01 21:22:10,599: INFO: common: yaml file : params.yaml loaded successfully]
[2025-01-01 21:22:10,601: INFO: common: yaml file : schema.yaml loaded successfully]
[2025-01-01 21:22:10,603: INFO: common: created directory at artifacts]
[2025-01-01 21:22:10,603: INFO: common: created directory at artifacts/data_validation]
[2025-01-01 21:22:10,615: INFO: main: >>>>>stage DATA VALIDATION STAGE completed <<<<<<<]
[2025-01-01 21:22:10,616: INFO: main: >>>>>>stage DATA TRANSFORMATION STAGE started<<<<<<]
[2025-01-01 21:22:10,618: INFO: common: yaml file : config\config.yaml loaded successfully]
[2025-01-01 21:22:10,619: INFO: common: yaml file : params.yaml loaded successfully]
[2025-01-01 21:22:10,621: INFO: common: yaml file : schema.yaml loaded successfully]
[2025-01-01 21:22:10,622: INFO: common: created directory at artifacts]
[2025-01-01 21:22:10,623: INFO: common: created directory at artifacts/data_transformation]
[2025-01-01 21:22:10,653: INFO: data_transformation: Splitted the data into train and test]
[2025-01-01 21:22:10,656: INFO: data_transformation: (1199, 12)]
[2025-01-01 21:22:10,657: INFO: data_transformation: (400, 12)]
[2025-01-01 21:22:10,659: INFO: main: >>>>>stage DATA TRANSFORMATION STAGE completed <<<<<<<]
[2025-01-01 21:22:10,659: INFO: main: >>>>>>stage MODEL TRAINING STAGE started<<<<<<]
[2025-01-01 21:22:10,662: INFO: common: yaml file : config\config.yaml loaded successfully]
[2025-01-01 21:22:10,664: INFO: common: yaml file : params.yaml loaded successfully]
[2025-01-01 21:22:10,667: INFO: common: yaml file : schema.yaml loaded successfully]
[2025-01-01 21:22:10,668: INFO: common: created directory at artifacts]
[2025-01-01 21:22:10,669: INFO: common: created directory at artifacts/model_trainer]
[2025-01-01 21:22:10,670: ERROR: main: "'ConfigBox' object has no attribute 'l1_ratio'"]
Traceback (most recent call last):
  File "box\\box.py", line 593, in box.box.Box.__getitem__
KeyError: 'l1_ratio'

The above exception was the direct cause of the following exception:

Traceback (most recent call last):
  File "box\\box.py", line 632, in box.box.Box.__getattr__
  File "box\\box.py", line 620, in box.box.Box.__getitem__
box.exceptions.BoxKeyError: "'l1_ratio'"

During handling of the above exception, another exception occurred:

Traceback (most recent call last):
  File "box\\box.py", line 634, in box.box.Box.__getattr__
AttributeError: 'ConfigBox' object has no attribute 'l1_ratio'

The above exception was the direct cause of the following exception:

Traceback (most recent call last):
  File "box\\config_box.py", line 29, in box.config_box.ConfigBox.__getattr__
  File "box\\box.py", line 648, in box.box.Box.__getattr__
box.exceptions.BoxKeyError: "'ConfigBox' object has no attribute 'l1_ratio'"

During handling of the above exception, another exception occurred:

Traceback (most recent call last):
  File "box\\box.py", line 593, in box.box.Box.__getitem__
KeyError: 'l1_ratio'

The above exception was the direct cause of the following exception:

Traceback (most recent call last):
  File "box\\box.py", line 632, in box.box.Box.__getattr__
  File "box\\box.py", line 620, in box.box.Box.__getitem__
box.exceptions.BoxKeyError: "'l1_ratio'"

During handling of the above exception, another exception occurred:

Traceback (most recent call last):
  File "box\\box.py", line 634, in box.box.Box.__getattr__
AttributeError: 'ConfigBox' object has no attribute 'l1_ratio'

The above exception was the direct cause of the following exception:

Traceback (most recent call last):
  File "C:\Users\sunny\Desktop\MLOps\Data_science_project1\main.py", line 41, in <module>
    obj.initiate_model_trainer()
  File "C:\Users\sunny\Desktop\MLOps\Data_science_project1\src\datascience\pipeline\model_trainer_pipeline.py", line 13, in initiate_model_trainer
    model_trainer_config=config.get_model_trainer_config()
                         ^^^^^^^^^^^^^^^^^^^^^^^^^^^^^^^^^
  File "C:\Users\sunny\Desktop\MLOps\Data_science_project1\src\datascience\config\configuration.py", line 86, in get_model_trainer_config
    l1_ratio=params.l1_ratio,
             ^^^^^^^^^^^^^^^
  File "box\\config_box.py", line 31, in box.config_box.ConfigBox.__getattr__
  File "box\\box.py", line 648, in box.box.Box.__getattr__
box.exceptions.BoxKeyError: "'ConfigBox' object has no attribute 'l1_ratio'"
[2025-01-01 21:22:35,832: INFO: main: >>>>>>stage DATA INGESTION STAGE started<<<<<<]
[2025-01-01 21:22:35,834: INFO: common: yaml file : config\config.yaml loaded successfully]
[2025-01-01 21:22:35,835: INFO: common: yaml file : params.yaml loaded successfully]
[2025-01-01 21:22:35,837: INFO: common: yaml file : schema.yaml loaded successfully]
[2025-01-01 21:22:35,838: INFO: common: created directory at artifacts]
[2025-01-01 21:22:35,838: INFO: common: created directory at artifacts/data_ingestion]
[2025-01-01 21:22:35,839: INFO: data_ingestion: File already exist]
[2025-01-01 21:22:35,841: INFO: main: >>>>>stage DATA INGESTION STAGE completed <<<<<<<]
[2025-01-01 21:22:35,842: INFO: main: >>>>>>stage DATA VALIDATION STAGE started<<<<<<]
[2025-01-01 21:22:35,843: INFO: common: yaml file : config\config.yaml loaded successfully]
[2025-01-01 21:22:35,844: INFO: common: yaml file : params.yaml loaded successfully]
[2025-01-01 21:22:35,846: INFO: common: yaml file : schema.yaml loaded successfully]
[2025-01-01 21:22:35,847: INFO: common: created directory at artifacts]
[2025-01-01 21:22:35,847: INFO: common: created directory at artifacts/data_validation]
[2025-01-01 21:22:35,856: INFO: main: >>>>>stage DATA VALIDATION STAGE completed <<<<<<<]
[2025-01-01 21:22:35,859: INFO: main: >>>>>>stage DATA TRANSFORMATION STAGE started<<<<<<]
[2025-01-01 21:22:35,861: INFO: common: yaml file : config\config.yaml loaded successfully]
[2025-01-01 21:22:35,862: INFO: common: yaml file : params.yaml loaded successfully]
[2025-01-01 21:22:35,863: INFO: common: yaml file : schema.yaml loaded successfully]
[2025-01-01 21:22:35,864: INFO: common: created directory at artifacts]
[2025-01-01 21:22:35,865: INFO: common: created directory at artifacts/data_transformation]
[2025-01-01 21:22:35,884: INFO: data_transformation: Splitted the data into train and test]
[2025-01-01 21:22:35,885: INFO: data_transformation: (1199, 12)]
[2025-01-01 21:22:35,885: INFO: data_transformation: (400, 12)]
[2025-01-01 21:22:35,886: INFO: main: >>>>>stage DATA TRANSFORMATION STAGE completed <<<<<<<]
[2025-01-01 21:22:35,886: INFO: main: >>>>>>stage MODEL TRAINING STAGE started<<<<<<]
[2025-01-01 21:22:35,888: INFO: common: yaml file : config\config.yaml loaded successfully]
[2025-01-01 21:22:35,895: INFO: common: yaml file : params.yaml loaded successfully]
[2025-01-01 21:22:35,897: INFO: common: yaml file : schema.yaml loaded successfully]
[2025-01-01 21:22:35,898: INFO: common: created directory at artifacts]
[2025-01-01 21:22:35,899: INFO: common: created directory at artifacts/model_trainer]
[2025-01-01 21:22:35,899: ERROR: main: "'ConfigBox' object has no attribute 'target_column'"]
Traceback (most recent call last):
  File "box\\box.py", line 593, in box.box.Box.__getitem__
KeyError: 'target_column'

The above exception was the direct cause of the following exception:

Traceback (most recent call last):
  File "box\\box.py", line 632, in box.box.Box.__getattr__
  File "box\\box.py", line 620, in box.box.Box.__getitem__
box.exceptions.BoxKeyError: "'target_column'"

During handling of the above exception, another exception occurred:

Traceback (most recent call last):
  File "box\\box.py", line 634, in box.box.Box.__getattr__
AttributeError: 'ConfigBox' object has no attribute 'target_column'

The above exception was the direct cause of the following exception:

Traceback (most recent call last):
  File "box\\config_box.py", line 29, in box.config_box.ConfigBox.__getattr__
  File "box\\box.py", line 648, in box.box.Box.__getattr__
box.exceptions.BoxKeyError: "'ConfigBox' object has no attribute 'target_column'"

During handling of the above exception, another exception occurred:

Traceback (most recent call last):
  File "box\\box.py", line 593, in box.box.Box.__getitem__
KeyError: 'target_column'

The above exception was the direct cause of the following exception:

Traceback (most recent call last):
  File "box\\box.py", line 632, in box.box.Box.__getattr__
  File "box\\box.py", line 620, in box.box.Box.__getitem__
box.exceptions.BoxKeyError: "'target_column'"

During handling of the above exception, another exception occurred:

Traceback (most recent call last):
  File "box\\box.py", line 634, in box.box.Box.__getattr__
AttributeError: 'ConfigBox' object has no attribute 'target_column'

The above exception was the direct cause of the following exception:

Traceback (most recent call last):
  File "C:\Users\sunny\Desktop\MLOps\Data_science_project1\main.py", line 41, in <module>
    obj.initiate_model_trainer()
  File "C:\Users\sunny\Desktop\MLOps\Data_science_project1\src\datascience\pipeline\model_trainer_pipeline.py", line 13, in initiate_model_trainer
    model_trainer_config=config.get_model_trainer_config()
                         ^^^^^^^^^^^^^^^^^^^^^^^^^^^^^^^^^
  File "C:\Users\sunny\Desktop\MLOps\Data_science_project1\src\datascience\config\configuration.py", line 87, in get_model_trainer_config
    target_column=schema.target_column
                  ^^^^^^^^^^^^^^^^^^^^
  File "box\\config_box.py", line 31, in box.config_box.ConfigBox.__getattr__
  File "box\\box.py", line 648, in box.box.Box.__getattr__
box.exceptions.BoxKeyError: "'ConfigBox' object has no attribute 'target_column'"
[2025-01-01 21:23:17,847: INFO: main: >>>>>>stage DATA INGESTION STAGE started<<<<<<]
[2025-01-01 21:23:17,847: INFO: common: yaml file : config\config.yaml loaded successfully]
[2025-01-01 21:23:17,847: INFO: common: yaml file : params.yaml loaded successfully]
[2025-01-01 21:23:17,847: INFO: common: yaml file : schema.yaml loaded successfully]
[2025-01-01 21:23:17,847: INFO: common: created directory at artifacts]
[2025-01-01 21:23:17,847: INFO: common: created directory at artifacts/data_ingestion]
[2025-01-01 21:23:17,857: INFO: data_ingestion: File already exist]
[2025-01-01 21:23:17,860: INFO: main: >>>>>stage DATA INGESTION STAGE completed <<<<<<<]
[2025-01-01 21:23:17,865: INFO: main: >>>>>>stage DATA VALIDATION STAGE started<<<<<<]
[2025-01-01 21:23:17,868: INFO: common: yaml file : config\config.yaml loaded successfully]
[2025-01-01 21:23:17,869: INFO: common: yaml file : params.yaml loaded successfully]
[2025-01-01 21:23:17,872: INFO: common: yaml file : schema.yaml loaded successfully]
[2025-01-01 21:23:17,873: INFO: common: created directory at artifacts]
[2025-01-01 21:23:17,873: INFO: common: created directory at artifacts/data_validation]
[2025-01-01 21:23:17,888: INFO: main: >>>>>stage DATA VALIDATION STAGE completed <<<<<<<]
[2025-01-01 21:23:17,889: INFO: main: >>>>>>stage DATA TRANSFORMATION STAGE started<<<<<<]
[2025-01-01 21:23:17,892: INFO: common: yaml file : config\config.yaml loaded successfully]
[2025-01-01 21:23:17,893: INFO: common: yaml file : params.yaml loaded successfully]
[2025-01-01 21:23:17,902: INFO: common: yaml file : schema.yaml loaded successfully]
[2025-01-01 21:23:17,903: INFO: common: created directory at artifacts]
[2025-01-01 21:23:17,904: INFO: common: created directory at artifacts/data_transformation]
[2025-01-01 21:23:17,930: INFO: data_transformation: Splitted the data into train and test]
[2025-01-01 21:23:17,931: INFO: data_transformation: (1199, 12)]
[2025-01-01 21:23:17,931: INFO: data_transformation: (400, 12)]
[2025-01-01 21:23:17,932: INFO: main: >>>>>stage DATA TRANSFORMATION STAGE completed <<<<<<<]
[2025-01-01 21:23:17,933: INFO: main: >>>>>>stage MODEL TRAINING STAGE started<<<<<<]
[2025-01-01 21:23:17,937: INFO: common: yaml file : config\config.yaml loaded successfully]
[2025-01-01 21:23:17,943: INFO: common: yaml file : params.yaml loaded successfully]
[2025-01-01 21:23:17,945: INFO: common: yaml file : schema.yaml loaded successfully]
[2025-01-01 21:23:17,946: INFO: common: created directory at artifacts]
[2025-01-01 21:23:17,947: INFO: common: created directory at artifacts/model_trainer]
[2025-01-01 21:23:17,947: ERROR: main: ModelTrainerConfig.__init__() got an unexpected keyword argument 'l1_ratio']
Traceback (most recent call last):
  File "C:\Users\sunny\Desktop\MLOps\Data_science_project1\main.py", line 41, in <module>
    obj.initiate_model_trainer()
  File "C:\Users\sunny\Desktop\MLOps\Data_science_project1\src\datascience\pipeline\model_trainer_pipeline.py", line 13, in initiate_model_trainer
    model_trainer_config=config.get_model_trainer_config()
                         ^^^^^^^^^^^^^^^^^^^^^^^^^^^^^^^^^
  File "C:\Users\sunny\Desktop\MLOps\Data_science_project1\src\datascience\config\configuration.py", line 80, in get_model_trainer_config
    model_trainer_config=ModelTrainerConfig(
                         ^^^^^^^^^^^^^^^^^^^
TypeError: ModelTrainerConfig.__init__() got an unexpected keyword argument 'l1_ratio'
[2025-01-01 21:27:24,003: INFO: main: >>>>>>stage DATA INGESTION STAGE started<<<<<<]
[2025-01-01 21:27:24,005: INFO: common: yaml file : config\config.yaml loaded successfully]
[2025-01-01 21:27:24,006: INFO: common: yaml file : params.yaml loaded successfully]
[2025-01-01 21:27:24,008: INFO: common: yaml file : schema.yaml loaded successfully]
[2025-01-01 21:27:24,008: INFO: common: created directory at artifacts]
[2025-01-01 21:27:24,009: INFO: common: created directory at artifacts/data_ingestion]
[2025-01-01 21:27:24,009: INFO: data_ingestion: File already exist]
[2025-01-01 21:27:24,013: INFO: main: >>>>>stage DATA INGESTION STAGE completed <<<<<<<]
[2025-01-01 21:27:24,013: INFO: main: >>>>>>stage DATA VALIDATION STAGE started<<<<<<]
[2025-01-01 21:27:24,015: INFO: common: yaml file : config\config.yaml loaded successfully]
[2025-01-01 21:27:24,016: INFO: common: yaml file : params.yaml loaded successfully]
[2025-01-01 21:27:24,018: INFO: common: yaml file : schema.yaml loaded successfully]
[2025-01-01 21:27:24,024: INFO: common: created directory at artifacts]
[2025-01-01 21:27:24,025: INFO: common: created directory at artifacts/data_validation]
[2025-01-01 21:27:24,035: INFO: main: >>>>>stage DATA VALIDATION STAGE completed <<<<<<<]
[2025-01-01 21:27:24,040: INFO: main: >>>>>>stage DATA TRANSFORMATION STAGE started<<<<<<]
[2025-01-01 21:27:24,043: INFO: common: yaml file : config\config.yaml loaded successfully]
[2025-01-01 21:27:24,044: INFO: common: yaml file : params.yaml loaded successfully]
[2025-01-01 21:27:24,046: INFO: common: yaml file : schema.yaml loaded successfully]
[2025-01-01 21:27:24,046: INFO: common: created directory at artifacts]
[2025-01-01 21:27:24,047: INFO: common: created directory at artifacts/data_transformation]
[2025-01-01 21:27:24,071: INFO: data_transformation: Splitted the data into train and test]
[2025-01-01 21:27:24,078: INFO: data_transformation: (1199, 12)]
[2025-01-01 21:27:24,079: INFO: data_transformation: (400, 12)]
[2025-01-01 21:27:24,080: INFO: main: >>>>>stage DATA TRANSFORMATION STAGE completed <<<<<<<]
[2025-01-01 21:27:24,080: INFO: main: >>>>>>stage MODEL TRAINING STAGE started<<<<<<]
[2025-01-01 21:27:24,082: INFO: common: yaml file : config\config.yaml loaded successfully]
[2025-01-01 21:27:24,084: INFO: common: yaml file : params.yaml loaded successfully]
[2025-01-01 21:27:24,095: INFO: common: yaml file : schema.yaml loaded successfully]
[2025-01-01 21:27:24,096: INFO: common: created directory at artifacts]
[2025-01-01 21:27:24,097: INFO: common: created directory at artifacts/model_trainer]
[2025-01-01 21:27:24,097: ERROR: main: name 'model_trainerModelTrainer' is not defined]
Traceback (most recent call last):
  File "C:\Users\sunny\Desktop\MLOps\Data_science_project1\main.py", line 41, in <module>
    obj.initiate_model_trainer()
  File "C:\Users\sunny\Desktop\MLOps\Data_science_project1\src\datascience\pipeline\model_trainer_pipeline.py", line 14, in initiate_model_trainer
    model_trainerModelTrainer(config=model_trainer_config)
    ^^^^^^^^^^^^^^^^^^^^^^^^^
NameError: name 'model_trainerModelTrainer' is not defined
[2025-01-01 21:28:36,767: INFO: main: >>>>>>stage DATA INGESTION STAGE started<<<<<<]
[2025-01-01 21:28:36,767: INFO: common: yaml file : config\config.yaml loaded successfully]
[2025-01-01 21:28:36,767: INFO: common: yaml file : params.yaml loaded successfully]
[2025-01-01 21:28:36,767: INFO: common: yaml file : schema.yaml loaded successfully]
[2025-01-01 21:28:36,767: INFO: common: created directory at artifacts]
[2025-01-01 21:28:36,767: INFO: common: created directory at artifacts/data_ingestion]
[2025-01-01 21:28:36,778: INFO: data_ingestion: File already exist]
[2025-01-01 21:28:36,779: INFO: main: >>>>>stage DATA INGESTION STAGE completed <<<<<<<]
[2025-01-01 21:28:36,784: INFO: main: >>>>>>stage DATA VALIDATION STAGE started<<<<<<]
[2025-01-01 21:28:36,786: INFO: common: yaml file : config\config.yaml loaded successfully]
[2025-01-01 21:28:36,787: INFO: common: yaml file : params.yaml loaded successfully]
[2025-01-01 21:28:36,789: INFO: common: yaml file : schema.yaml loaded successfully]
[2025-01-01 21:28:36,795: INFO: common: created directory at artifacts]
[2025-01-01 21:28:36,796: INFO: common: created directory at artifacts/data_validation]
[2025-01-01 21:28:36,805: INFO: main: >>>>>stage DATA VALIDATION STAGE completed <<<<<<<]
[2025-01-01 21:28:36,805: INFO: main: >>>>>>stage DATA TRANSFORMATION STAGE started<<<<<<]
[2025-01-01 21:28:36,808: INFO: common: yaml file : config\config.yaml loaded successfully]
[2025-01-01 21:28:36,813: INFO: common: yaml file : params.yaml loaded successfully]
[2025-01-01 21:28:36,816: INFO: common: yaml file : schema.yaml loaded successfully]
[2025-01-01 21:28:36,817: INFO: common: created directory at artifacts]
[2025-01-01 21:28:36,818: INFO: common: created directory at artifacts/data_transformation]
[2025-01-01 21:28:36,836: INFO: data_transformation: Splitted the data into train and test]
[2025-01-01 21:28:36,837: INFO: data_transformation: (1199, 12)]
[2025-01-01 21:28:36,837: INFO: data_transformation: (400, 12)]
[2025-01-01 21:28:36,837: INFO: main: >>>>>stage DATA TRANSFORMATION STAGE completed <<<<<<<]
[2025-01-01 21:28:36,839: INFO: main: >>>>>>stage MODEL TRAINING STAGE started<<<<<<]
[2025-01-01 21:28:36,841: INFO: common: yaml file : config\config.yaml loaded successfully]
[2025-01-01 21:28:36,846: INFO: common: yaml file : params.yaml loaded successfully]
[2025-01-01 21:28:36,848: INFO: common: yaml file : schema.yaml loaded successfully]
[2025-01-01 21:28:36,849: INFO: common: created directory at artifacts]
[2025-01-01 21:28:36,850: INFO: common: created directory at artifacts/model_trainer]
[2025-01-01 21:28:36,888: INFO: main: >>>>>stage MODEL TRAINING STAGE completed <<<<<<<]
[2025-01-01 22:36:15,819: INFO: main: >>>>>>stage DATA INGESTION STAGE started<<<<<<]
[2025-01-01 22:36:15,834: INFO: common: yaml file : config\config.yaml loaded successfully]
[2025-01-01 22:36:15,834: INFO: common: yaml file : params.yaml loaded successfully]
[2025-01-01 22:36:15,834: INFO: common: yaml file : schema.yaml loaded successfully]
[2025-01-01 22:36:15,834: INFO: common: created directory at artifacts]
[2025-01-01 22:36:15,840: INFO: common: created directory at artifacts/data_ingestion]
[2025-01-01 22:36:15,840: INFO: data_ingestion: File already exist]
[2025-01-01 22:36:15,846: INFO: main: >>>>>stage DATA INGESTION STAGE completed <<<<<<<]
[2025-01-01 22:36:15,848: INFO: main: >>>>>>stage DATA VALIDATION STAGE started<<<<<<]
[2025-01-01 22:36:15,851: INFO: common: yaml file : config\config.yaml loaded successfully]
[2025-01-01 22:36:15,853: INFO: common: yaml file : params.yaml loaded successfully]
[2025-01-01 22:36:15,854: INFO: common: yaml file : schema.yaml loaded successfully]
[2025-01-01 22:36:15,855: INFO: common: created directory at artifacts]
[2025-01-01 22:36:15,856: INFO: common: created directory at artifacts/data_validation]
[2025-01-01 22:36:15,882: INFO: main: >>>>>stage DATA VALIDATION STAGE completed <<<<<<<]
[2025-01-01 22:36:15,882: INFO: main: >>>>>>stage DATA TRANSFORMATION STAGE started<<<<<<]
[2025-01-01 22:36:15,885: INFO: common: yaml file : config\config.yaml loaded successfully]
[2025-01-01 22:36:15,885: INFO: common: yaml file : params.yaml loaded successfully]
[2025-01-01 22:36:15,887: INFO: common: yaml file : schema.yaml loaded successfully]
[2025-01-01 22:36:15,888: INFO: common: created directory at artifacts]
[2025-01-01 22:36:15,888: INFO: common: created directory at artifacts/data_transformation]
[2025-01-01 22:36:15,920: INFO: data_transformation: Splitted the data into train and test]
[2025-01-01 22:36:15,921: INFO: data_transformation: (1199, 12)]
[2025-01-01 22:36:15,921: INFO: data_transformation: (400, 12)]
[2025-01-01 22:36:15,922: INFO: main: >>>>>stage DATA TRANSFORMATION STAGE completed <<<<<<<]
[2025-01-01 22:36:15,922: INFO: main: >>>>>>stage MODEL TRAINING STAGE started<<<<<<]
[2025-01-01 22:36:15,927: INFO: common: yaml file : config\config.yaml loaded successfully]
[2025-01-01 22:36:15,932: INFO: common: yaml file : params.yaml loaded successfully]
[2025-01-01 22:36:15,934: INFO: common: yaml file : schema.yaml loaded successfully]
[2025-01-01 22:36:15,935: INFO: common: created directory at artifacts]
[2025-01-01 22:36:15,936: INFO: common: created directory at artifacts/model_trainer]
[2025-01-01 22:36:15,956: INFO: main: >>>>>stage MODEL TRAINING STAGE completed <<<<<<<]
[2025-01-01 22:36:15,963: INFO: main: >>>>>>stage MODEL EVALUATION STAGE started<<<<<<]
[2025-01-01 22:36:15,963: ERROR: main: name 'ModelEvaluationPipeline' is not defined]
Traceback (most recent call last):
  File "C:\Users\sunny\Desktop\MLOps\Data_science_project1\main.py", line 50, in <module>
    obj=ModelEvaluationPipeline()
        ^^^^^^^^^^^^^^^^^^^^^^^
NameError: name 'ModelEvaluationPipeline' is not defined
[2025-01-01 22:38:29,129: INFO: main: >>>>>>stage DATA INGESTION STAGE started<<<<<<]
[2025-01-01 22:38:29,131: INFO: common: yaml file : config\config.yaml loaded successfully]
[2025-01-01 22:38:29,132: INFO: common: yaml file : params.yaml loaded successfully]
[2025-01-01 22:38:29,133: INFO: common: yaml file : schema.yaml loaded successfully]
[2025-01-01 22:38:29,134: INFO: common: created directory at artifacts]
[2025-01-01 22:38:29,134: INFO: common: created directory at artifacts/data_ingestion]
[2025-01-01 22:38:29,134: INFO: data_ingestion: File already exist]
[2025-01-01 22:38:29,137: INFO: main: >>>>>stage DATA INGESTION STAGE completed <<<<<<<]
[2025-01-01 22:38:29,138: INFO: main: >>>>>>stage DATA VALIDATION STAGE started<<<<<<]
[2025-01-01 22:38:29,140: INFO: common: yaml file : config\config.yaml loaded successfully]
[2025-01-01 22:38:29,140: INFO: common: yaml file : params.yaml loaded successfully]
[2025-01-01 22:38:29,142: INFO: common: yaml file : schema.yaml loaded successfully]
[2025-01-01 22:38:29,143: INFO: common: created directory at artifacts]
[2025-01-01 22:38:29,143: INFO: common: created directory at artifacts/data_validation]
[2025-01-01 22:38:29,154: INFO: main: >>>>>stage DATA VALIDATION STAGE completed <<<<<<<]
[2025-01-01 22:38:29,154: INFO: main: >>>>>>stage DATA TRANSFORMATION STAGE started<<<<<<]
[2025-01-01 22:38:29,156: INFO: common: yaml file : config\config.yaml loaded successfully]
[2025-01-01 22:38:29,162: INFO: common: yaml file : params.yaml loaded successfully]
[2025-01-01 22:38:29,166: INFO: common: yaml file : schema.yaml loaded successfully]
[2025-01-01 22:38:29,167: INFO: common: created directory at artifacts]
[2025-01-01 22:38:29,167: INFO: common: created directory at artifacts/data_transformation]
[2025-01-01 22:38:29,188: INFO: data_transformation: Splitted the data into train and test]
[2025-01-01 22:38:29,195: INFO: data_transformation: (1199, 12)]
[2025-01-01 22:38:29,196: INFO: data_transformation: (400, 12)]
[2025-01-01 22:38:29,197: INFO: main: >>>>>stage DATA TRANSFORMATION STAGE completed <<<<<<<]
[2025-01-01 22:38:29,197: INFO: main: >>>>>>stage MODEL TRAINING STAGE started<<<<<<]
[2025-01-01 22:38:29,201: INFO: common: yaml file : config\config.yaml loaded successfully]
[2025-01-01 22:38:29,201: INFO: common: yaml file : params.yaml loaded successfully]
[2025-01-01 22:38:29,203: INFO: common: yaml file : schema.yaml loaded successfully]
[2025-01-01 22:38:29,204: INFO: common: created directory at artifacts]
[2025-01-01 22:38:29,205: INFO: common: created directory at artifacts/model_trainer]
[2025-01-01 22:38:29,222: INFO: main: >>>>>stage MODEL TRAINING STAGE completed <<<<<<<]
[2025-01-01 22:38:29,229: INFO: main: >>>>>>stage MODEL EVALUATION STAGE started<<<<<<]
[2025-01-01 22:38:29,230: ERROR: main: name 'ModelEvaluationPipeline' is not defined]
Traceback (most recent call last):
  File "C:\Users\sunny\Desktop\MLOps\Data_science_project1\main.py", line 50, in <module>
    obj=ModelEvaluationPipeline()
        ^^^^^^^^^^^^^^^^^^^^^^^
NameError: name 'ModelEvaluationPipeline' is not defined
[2025-01-01 22:43:29,404: INFO: main: >>>>>>stage DATA INGESTION STAGE started<<<<<<]
[2025-01-01 22:43:29,404: INFO: common: yaml file : config\config.yaml loaded successfully]
[2025-01-01 22:43:29,404: INFO: common: yaml file : params.yaml loaded successfully]
[2025-01-01 22:43:29,404: INFO: common: yaml file : schema.yaml loaded successfully]
[2025-01-01 22:43:29,404: INFO: common: created directory at artifacts]
[2025-01-01 22:43:29,404: INFO: common: created directory at artifacts/data_ingestion]
[2025-01-01 22:43:29,404: INFO: data_ingestion: File already exist]
[2025-01-01 22:43:29,404: INFO: main: >>>>>stage DATA INGESTION STAGE completed <<<<<<<]
[2025-01-01 22:43:29,404: INFO: main: >>>>>>stage DATA VALIDATION STAGE started<<<<<<]
[2025-01-01 22:43:29,404: INFO: common: yaml file : config\config.yaml loaded successfully]
[2025-01-01 22:43:29,420: INFO: common: yaml file : params.yaml loaded successfully]
[2025-01-01 22:43:29,422: INFO: common: yaml file : schema.yaml loaded successfully]
[2025-01-01 22:43:29,430: INFO: common: created directory at artifacts]
[2025-01-01 22:43:29,431: INFO: common: created directory at artifacts/data_validation]
[2025-01-01 22:43:29,441: INFO: main: >>>>>stage DATA VALIDATION STAGE completed <<<<<<<]
[2025-01-01 22:43:29,446: INFO: main: >>>>>>stage DATA TRANSFORMATION STAGE started<<<<<<]
[2025-01-01 22:43:29,449: INFO: common: yaml file : config\config.yaml loaded successfully]
[2025-01-01 22:43:29,450: INFO: common: yaml file : params.yaml loaded successfully]
[2025-01-01 22:43:29,452: INFO: common: yaml file : schema.yaml loaded successfully]
[2025-01-01 22:43:29,452: INFO: common: created directory at artifacts]
[2025-01-01 22:43:29,453: INFO: common: created directory at artifacts/data_transformation]
[2025-01-01 22:43:29,473: INFO: data_transformation: Splitted the data into train and test]
[2025-01-01 22:43:29,474: INFO: data_transformation: (1199, 12)]
[2025-01-01 22:43:29,474: INFO: data_transformation: (400, 12)]
[2025-01-01 22:43:29,475: INFO: main: >>>>>stage DATA TRANSFORMATION STAGE completed <<<<<<<]
[2025-01-01 22:43:29,475: INFO: main: >>>>>>stage MODEL TRAINING STAGE started<<<<<<]
[2025-01-01 22:43:29,477: INFO: common: yaml file : config\config.yaml loaded successfully]
[2025-01-01 22:43:29,478: INFO: common: yaml file : params.yaml loaded successfully]
[2025-01-01 22:43:29,480: INFO: common: yaml file : schema.yaml loaded successfully]
[2025-01-01 22:43:29,481: INFO: common: created directory at artifacts]
[2025-01-01 22:43:29,482: INFO: common: created directory at artifacts/model_trainer]
[2025-01-01 22:43:29,499: INFO: main: >>>>>stage MODEL TRAINING STAGE completed <<<<<<<]
[2025-01-01 22:43:29,506: INFO: main: >>>>>>stage MODEL EVALUATION STAGE started<<<<<<]
[2025-01-01 22:43:29,508: INFO: common: yaml file : config\config.yaml loaded successfully]
[2025-01-01 22:43:29,509: INFO: common: yaml file : params.yaml loaded successfully]
[2025-01-01 22:43:29,511: INFO: common: yaml file : schema.yaml loaded successfully]
[2025-01-01 22:43:29,512: INFO: common: created directory at artifacts]
[2025-01-01 22:43:29,513: INFO: common: created directory at artifacts/model_evaluation]
[2025-01-01 22:43:29,526: ERROR: main: 'ModelEvaluation' object has no attribute 'cofig']
Traceback (most recent call last):
  File "C:\Users\sunny\Desktop\MLOps\Data_science_project1\main.py", line 52, in <module>
    obj.initiate_model_evaluation()
  File "C:\Users\sunny\Desktop\MLOps\Data_science_project1\src\datascience\pipeline\model_evaluation_pipeline.py", line 15, in initiate_model_evaluation
    model_evaluation.log_into_mlflow()
  File "C:\Users\sunny\Desktop\MLOps\Data_science_project1\src\datascience\components\model_evaluation.py", line 33, in log_into_mlflow
    test_y=test_data[[self.cofig.target_column]]
                      ^^^^^^^^^^
AttributeError: 'ModelEvaluation' object has no attribute 'cofig'
[2025-01-01 22:44:10,176: INFO: main: >>>>>>stage DATA INGESTION STAGE started<<<<<<]
[2025-01-01 22:44:10,191: INFO: common: yaml file : config\config.yaml loaded successfully]
[2025-01-01 22:44:10,191: INFO: common: yaml file : params.yaml loaded successfully]
[2025-01-01 22:44:10,191: INFO: common: yaml file : schema.yaml loaded successfully]
[2025-01-01 22:44:10,191: INFO: common: created directory at artifacts]
[2025-01-01 22:44:10,191: INFO: common: created directory at artifacts/data_ingestion]
[2025-01-01 22:44:10,191: INFO: data_ingestion: File already exist]
[2025-01-01 22:44:10,191: INFO: main: >>>>>stage DATA INGESTION STAGE completed <<<<<<<]
[2025-01-01 22:44:10,191: INFO: main: >>>>>>stage DATA VALIDATION STAGE started<<<<<<]
[2025-01-01 22:44:10,191: INFO: common: yaml file : config\config.yaml loaded successfully]
[2025-01-01 22:44:10,204: INFO: common: yaml file : params.yaml loaded successfully]
[2025-01-01 22:44:10,207: INFO: common: yaml file : schema.yaml loaded successfully]
[2025-01-01 22:44:10,213: INFO: common: created directory at artifacts]
[2025-01-01 22:44:10,214: INFO: common: created directory at artifacts/data_validation]
[2025-01-01 22:44:10,226: INFO: main: >>>>>stage DATA VALIDATION STAGE completed <<<<<<<]
[2025-01-01 22:44:10,235: INFO: main: >>>>>>stage DATA TRANSFORMATION STAGE started<<<<<<]
[2025-01-01 22:44:10,240: INFO: common: yaml file : config\config.yaml loaded successfully]
[2025-01-01 22:44:10,243: INFO: common: yaml file : params.yaml loaded successfully]
[2025-01-01 22:44:10,245: INFO: common: yaml file : schema.yaml loaded successfully]
[2025-01-01 22:44:10,246: INFO: common: created directory at artifacts]
[2025-01-01 22:44:10,247: INFO: common: created directory at artifacts/data_transformation]
[2025-01-01 22:44:10,274: INFO: data_transformation: Splitted the data into train and test]
[2025-01-01 22:44:10,282: INFO: data_transformation: (1199, 12)]
[2025-01-01 22:44:10,284: INFO: data_transformation: (400, 12)]
[2025-01-01 22:44:10,284: INFO: main: >>>>>stage DATA TRANSFORMATION STAGE completed <<<<<<<]
[2025-01-01 22:44:10,284: INFO: main: >>>>>>stage MODEL TRAINING STAGE started<<<<<<]
[2025-01-01 22:44:10,287: INFO: common: yaml file : config\config.yaml loaded successfully]
[2025-01-01 22:44:10,289: INFO: common: yaml file : params.yaml loaded successfully]
[2025-01-01 22:44:10,292: INFO: common: yaml file : schema.yaml loaded successfully]
[2025-01-01 22:44:10,293: INFO: common: created directory at artifacts]
[2025-01-01 22:44:10,294: INFO: common: created directory at artifacts/model_trainer]
[2025-01-01 22:44:10,313: INFO: main: >>>>>stage MODEL TRAINING STAGE completed <<<<<<<]
[2025-01-01 22:44:10,317: INFO: main: >>>>>>stage MODEL EVALUATION STAGE started<<<<<<]
[2025-01-01 22:44:10,320: INFO: common: yaml file : config\config.yaml loaded successfully]
[2025-01-01 22:44:10,321: INFO: common: yaml file : params.yaml loaded successfully]
[2025-01-01 22:44:10,323: INFO: common: yaml file : schema.yaml loaded successfully]
[2025-01-01 22:44:10,324: INFO: common: created directory at artifacts]
[2025-01-01 22:44:10,324: INFO: common: created directory at artifacts/model_evaluation]
[2025-01-01 22:44:12,631: ERROR: main: name 'np' is not defined]
Traceback (most recent call last):
  File "C:\Users\sunny\Desktop\MLOps\Data_science_project1\main.py", line 52, in <module>
    obj.initiate_model_evaluation()
  File "C:\Users\sunny\Desktop\MLOps\Data_science_project1\src\datascience\pipeline\model_evaluation_pipeline.py", line 15, in initiate_model_evaluation
    model_evaluation.log_into_mlflow()
  File "C:\Users\sunny\Desktop\MLOps\Data_science_project1\src\datascience\components\model_evaluation.py", line 42, in log_into_mlflow
    (rmse,mae,r2_score) = self.eval_metrics(test_y,predicted_qualities)
                          ^^^^^^^^^^^^^^^^^^^^^^^^^^^^^^^^^^^^^^^^^^^^^
  File "C:\Users\sunny\Desktop\MLOps\Data_science_project1\src\datascience\components\model_evaluation.py", line 22, in eval_metrics
    rmse=np.sqrt(mean_squared_error(actual,pred))
         ^^
NameError: name 'np' is not defined
[2025-01-01 22:44:39,685: INFO: main: >>>>>>stage DATA INGESTION STAGE started<<<<<<]
[2025-01-01 22:44:39,685: INFO: common: yaml file : config\config.yaml loaded successfully]
[2025-01-01 22:44:39,685: INFO: common: yaml file : params.yaml loaded successfully]
[2025-01-01 22:44:39,685: INFO: common: yaml file : schema.yaml loaded successfully]
[2025-01-01 22:44:39,685: INFO: common: created directory at artifacts]
[2025-01-01 22:44:39,685: INFO: common: created directory at artifacts/data_ingestion]
[2025-01-01 22:44:39,685: INFO: data_ingestion: File already exist]
[2025-01-01 22:44:39,701: INFO: main: >>>>>stage DATA INGESTION STAGE completed <<<<<<<]
[2025-01-01 22:44:39,701: INFO: main: >>>>>>stage DATA VALIDATION STAGE started<<<<<<]
[2025-01-01 22:44:39,701: INFO: common: yaml file : config\config.yaml loaded successfully]
[2025-01-01 22:44:39,706: INFO: common: yaml file : params.yaml loaded successfully]
[2025-01-01 22:44:39,709: INFO: common: yaml file : schema.yaml loaded successfully]
[2025-01-01 22:44:39,717: INFO: common: created directory at artifacts]
[2025-01-01 22:44:39,718: INFO: common: created directory at artifacts/data_validation]
[2025-01-01 22:44:39,738: INFO: main: >>>>>stage DATA VALIDATION STAGE completed <<<<<<<]
[2025-01-01 22:44:39,738: INFO: main: >>>>>>stage DATA TRANSFORMATION STAGE started<<<<<<]
[2025-01-01 22:44:39,743: INFO: common: yaml file : config\config.yaml loaded successfully]
[2025-01-01 22:44:39,747: INFO: common: yaml file : params.yaml loaded successfully]
[2025-01-01 22:44:39,750: INFO: common: yaml file : schema.yaml loaded successfully]
[2025-01-01 22:44:39,751: INFO: common: created directory at artifacts]
[2025-01-01 22:44:39,752: INFO: common: created directory at artifacts/data_transformation]
[2025-01-01 22:44:39,782: INFO: data_transformation: Splitted the data into train and test]
[2025-01-01 22:44:39,789: INFO: data_transformation: (1199, 12)]
[2025-01-01 22:44:39,790: INFO: data_transformation: (400, 12)]
[2025-01-01 22:44:39,791: INFO: main: >>>>>stage DATA TRANSFORMATION STAGE completed <<<<<<<]
[2025-01-01 22:44:39,793: INFO: main: >>>>>>stage MODEL TRAINING STAGE started<<<<<<]
[2025-01-01 22:44:39,800: INFO: common: yaml file : config\config.yaml loaded successfully]
[2025-01-01 22:44:39,802: INFO: common: yaml file : params.yaml loaded successfully]
[2025-01-01 22:44:39,806: INFO: common: yaml file : schema.yaml loaded successfully]
[2025-01-01 22:44:39,820: INFO: common: created directory at artifacts]
[2025-01-01 22:44:39,821: INFO: common: created directory at artifacts/model_trainer]
[2025-01-01 22:44:39,835: INFO: main: >>>>>stage MODEL TRAINING STAGE completed <<<<<<<]
[2025-01-01 22:44:39,836: INFO: main: >>>>>>stage MODEL EVALUATION STAGE started<<<<<<]
[2025-01-01 22:44:39,838: INFO: common: yaml file : config\config.yaml loaded successfully]
[2025-01-01 22:44:39,840: INFO: common: yaml file : params.yaml loaded successfully]
[2025-01-01 22:44:39,851: INFO: common: yaml file : schema.yaml loaded successfully]
[2025-01-01 22:44:39,851: INFO: common: created directory at artifacts]
[2025-01-01 22:44:39,852: INFO: common: created directory at artifacts/model_evaluation]
[2025-01-01 22:44:41,838: ERROR: main: cannot access local variable 'r2_score' where it is not associated with a value]
Traceback (most recent call last):
  File "C:\Users\sunny\Desktop\MLOps\Data_science_project1\main.py", line 52, in <module>
    obj.initiate_model_evaluation()
  File "C:\Users\sunny\Desktop\MLOps\Data_science_project1\src\datascience\pipeline\model_evaluation_pipeline.py", line 15, in initiate_model_evaluation
    model_evaluation.log_into_mlflow()
  File "C:\Users\sunny\Desktop\MLOps\Data_science_project1\src\datascience\components\model_evaluation.py", line 43, in log_into_mlflow
    (rmse,mae,r2_score) = self.eval_metrics(test_y,predicted_qualities)
                          ^^^^^^^^^^^^^^^^^^^^^^^^^^^^^^^^^^^^^^^^^^^^^
  File "C:\Users\sunny\Desktop\MLOps\Data_science_project1\src\datascience\components\model_evaluation.py", line 25, in eval_metrics
    r2_score=r2_score(actual,pred)
             ^^^^^^^^
UnboundLocalError: cannot access local variable 'r2_score' where it is not associated with a value
[2025-01-01 22:46:15,308: INFO: main: >>>>>>stage DATA INGESTION STAGE started<<<<<<]
[2025-01-01 22:46:15,311: INFO: common: yaml file : config\config.yaml loaded successfully]
[2025-01-01 22:46:15,312: INFO: common: yaml file : params.yaml loaded successfully]
[2025-01-01 22:46:15,314: INFO: common: yaml file : schema.yaml loaded successfully]
[2025-01-01 22:46:15,315: INFO: common: created directory at artifacts]
[2025-01-01 22:46:15,315: INFO: common: created directory at artifacts/data_ingestion]
[2025-01-01 22:46:15,316: INFO: data_ingestion: File already exist]
[2025-01-01 22:46:15,318: INFO: main: >>>>>stage DATA INGESTION STAGE completed <<<<<<<]
[2025-01-01 22:46:15,319: INFO: main: >>>>>>stage DATA VALIDATION STAGE started<<<<<<]
[2025-01-01 22:46:15,322: INFO: common: yaml file : config\config.yaml loaded successfully]
[2025-01-01 22:46:15,332: INFO: common: yaml file : params.yaml loaded successfully]
[2025-01-01 22:46:15,334: INFO: common: yaml file : schema.yaml loaded successfully]
[2025-01-01 22:46:15,335: INFO: common: created directory at artifacts]
[2025-01-01 22:46:15,336: INFO: common: created directory at artifacts/data_validation]
[2025-01-01 22:46:15,348: INFO: main: >>>>>stage DATA VALIDATION STAGE completed <<<<<<<]
[2025-01-01 22:46:15,357: INFO: main: >>>>>>stage DATA TRANSFORMATION STAGE started<<<<<<]
[2025-01-01 22:46:15,360: INFO: common: yaml file : config\config.yaml loaded successfully]
[2025-01-01 22:46:15,361: INFO: common: yaml file : params.yaml loaded successfully]
[2025-01-01 22:46:15,374: INFO: common: yaml file : schema.yaml loaded successfully]
[2025-01-01 22:46:15,376: INFO: common: created directory at artifacts]
[2025-01-01 22:46:15,377: INFO: common: created directory at artifacts/data_transformation]
[2025-01-01 22:46:15,401: INFO: data_transformation: Splitted the data into train and test]
[2025-01-01 22:46:15,401: INFO: data_transformation: (1199, 12)]
[2025-01-01 22:46:15,402: INFO: data_transformation: (400, 12)]
[2025-01-01 22:46:15,402: INFO: main: >>>>>stage DATA TRANSFORMATION STAGE completed <<<<<<<]
[2025-01-01 22:46:15,402: INFO: main: >>>>>>stage MODEL TRAINING STAGE started<<<<<<]
[2025-01-01 22:46:15,405: INFO: common: yaml file : config\config.yaml loaded successfully]
[2025-01-01 22:46:15,412: INFO: common: yaml file : params.yaml loaded successfully]
[2025-01-01 22:46:15,414: INFO: common: yaml file : schema.yaml loaded successfully]
[2025-01-01 22:46:15,415: INFO: common: created directory at artifacts]
[2025-01-01 22:46:15,416: INFO: common: created directory at artifacts/model_trainer]
[2025-01-01 22:46:15,428: INFO: main: >>>>>stage MODEL TRAINING STAGE completed <<<<<<<]
[2025-01-01 22:46:15,438: INFO: main: >>>>>>stage MODEL EVALUATION STAGE started<<<<<<]
[2025-01-01 22:46:15,440: INFO: common: yaml file : config\config.yaml loaded successfully]
[2025-01-01 22:46:15,441: INFO: common: yaml file : params.yaml loaded successfully]
[2025-01-01 22:46:15,443: INFO: common: yaml file : schema.yaml loaded successfully]
[2025-01-01 22:46:15,443: INFO: common: created directory at artifacts]
[2025-01-01 22:46:15,444: INFO: common: created directory at artifacts/model_evaluation]
[2025-01-01 22:46:17,440: ERROR: main: cannot access local variable 'r2_score' where it is not associated with a value]
Traceback (most recent call last):
  File "C:\Users\sunny\Desktop\MLOps\Data_science_project1\main.py", line 52, in <module>
    obj.initiate_model_evaluation()
  File "C:\Users\sunny\Desktop\MLOps\Data_science_project1\src\datascience\pipeline\model_evaluation_pipeline.py", line 15, in initiate_model_evaluation
    model_evaluation.log_into_mlflow()
  File "C:\Users\sunny\Desktop\MLOps\Data_science_project1\src\datascience\components\model_evaluation.py", line 43, in log_into_mlflow
    (rmse,mae,r2) = self.eval_metrics(test_y,predicted_qualities)
                    ^^^^^^^^^^^^^^^^^^^^^^^^^^^^^^^^^^^^^^^^^^^^^
  File "C:\Users\sunny\Desktop\MLOps\Data_science_project1\src\datascience\components\model_evaluation.py", line 25, in eval_metrics
    r2_score=r2_score(actual,pred)
             ^^^^^^^^
UnboundLocalError: cannot access local variable 'r2_score' where it is not associated with a value
[2025-01-01 22:47:46,065: INFO: main: >>>>>>stage DATA INGESTION STAGE started<<<<<<]
[2025-01-01 22:47:46,065: INFO: common: yaml file : config\config.yaml loaded successfully]
[2025-01-01 22:47:46,065: INFO: common: yaml file : params.yaml loaded successfully]
[2025-01-01 22:47:46,065: INFO: common: yaml file : schema.yaml loaded successfully]
[2025-01-01 22:47:46,065: INFO: common: created directory at artifacts]
[2025-01-01 22:47:46,065: INFO: common: created directory at artifacts/data_ingestion]
[2025-01-01 22:47:46,065: INFO: data_ingestion: File already exist]
[2025-01-01 22:47:46,065: INFO: main: >>>>>stage DATA INGESTION STAGE completed <<<<<<<]
[2025-01-01 22:47:46,080: INFO: main: >>>>>>stage DATA VALIDATION STAGE started<<<<<<]
[2025-01-01 22:47:46,082: INFO: common: yaml file : config\config.yaml loaded successfully]
[2025-01-01 22:47:46,082: INFO: common: yaml file : params.yaml loaded successfully]
[2025-01-01 22:47:46,091: INFO: common: yaml file : schema.yaml loaded successfully]
[2025-01-01 22:47:46,093: INFO: common: created directory at artifacts]
[2025-01-01 22:47:46,094: INFO: common: created directory at artifacts/data_validation]
[2025-01-01 22:47:46,108: INFO: main: >>>>>stage DATA VALIDATION STAGE completed <<<<<<<]
[2025-01-01 22:47:46,110: INFO: main: >>>>>>stage DATA TRANSFORMATION STAGE started<<<<<<]
[2025-01-01 22:47:46,115: INFO: common: yaml file : config\config.yaml loaded successfully]
[2025-01-01 22:47:46,129: INFO: common: yaml file : params.yaml loaded successfully]
[2025-01-01 22:47:46,132: INFO: common: yaml file : schema.yaml loaded successfully]
[2025-01-01 22:47:46,147: INFO: common: created directory at artifacts]
[2025-01-01 22:47:46,149: INFO: common: created directory at artifacts/data_transformation]
[2025-01-01 22:47:46,191: INFO: data_transformation: Splitted the data into train and test]
[2025-01-01 22:47:46,192: INFO: data_transformation: (1199, 12)]
[2025-01-01 22:47:46,192: INFO: data_transformation: (400, 12)]
[2025-01-01 22:47:46,193: INFO: main: >>>>>stage DATA TRANSFORMATION STAGE completed <<<<<<<]
[2025-01-01 22:47:46,193: INFO: main: >>>>>>stage MODEL TRAINING STAGE started<<<<<<]
[2025-01-01 22:47:46,196: INFO: common: yaml file : config\config.yaml loaded successfully]
[2025-01-01 22:47:46,197: INFO: common: yaml file : params.yaml loaded successfully]
[2025-01-01 22:47:46,199: INFO: common: yaml file : schema.yaml loaded successfully]
[2025-01-01 22:47:46,208: INFO: common: created directory at artifacts]
[2025-01-01 22:47:46,209: INFO: common: created directory at artifacts/model_trainer]
[2025-01-01 22:47:46,221: INFO: main: >>>>>stage MODEL TRAINING STAGE completed <<<<<<<]
[2025-01-01 22:47:46,225: INFO: main: >>>>>>stage MODEL EVALUATION STAGE started<<<<<<]
[2025-01-01 22:47:46,228: INFO: common: yaml file : config\config.yaml loaded successfully]
[2025-01-01 22:47:46,228: INFO: common: yaml file : params.yaml loaded successfully]
[2025-01-01 22:47:46,231: INFO: common: yaml file : schema.yaml loaded successfully]
[2025-01-01 22:47:46,231: INFO: common: created directory at artifacts]
[2025-01-01 22:47:46,231: INFO: common: created directory at artifacts/model_evaluation]
[2025-01-01 22:47:48,212: ERROR: main: name 'Path' is not defined]
Traceback (most recent call last):
  File "C:\Users\sunny\Desktop\MLOps\Data_science_project1\main.py", line 52, in <module>
    obj.initiate_model_evaluation()
  File "C:\Users\sunny\Desktop\MLOps\Data_science_project1\src\datascience\pipeline\model_evaluation_pipeline.py", line 15, in initiate_model_evaluation
    model_evaluation.log_into_mlflow()
  File "C:\Users\sunny\Desktop\MLOps\Data_science_project1\src\datascience\components\model_evaluation.py", line 47, in log_into_mlflow
    save_json(path=Path(self.config.metric_file_name),data=scores)
                   ^^^^
NameError: name 'Path' is not defined
[2025-01-01 22:48:40,966: INFO: main: >>>>>>stage DATA INGESTION STAGE started<<<<<<]
[2025-01-01 22:48:40,969: INFO: common: yaml file : config\config.yaml loaded successfully]
[2025-01-01 22:48:40,970: INFO: common: yaml file : params.yaml loaded successfully]
[2025-01-01 22:48:40,972: INFO: common: yaml file : schema.yaml loaded successfully]
[2025-01-01 22:48:40,973: INFO: common: created directory at artifacts]
[2025-01-01 22:48:40,973: INFO: common: created directory at artifacts/data_ingestion]
[2025-01-01 22:48:40,974: INFO: data_ingestion: File already exist]
[2025-01-01 22:48:40,976: INFO: main: >>>>>stage DATA INGESTION STAGE completed <<<<<<<]
[2025-01-01 22:48:40,976: INFO: main: >>>>>>stage DATA VALIDATION STAGE started<<<<<<]
[2025-01-01 22:48:40,979: INFO: common: yaml file : config\config.yaml loaded successfully]
[2025-01-01 22:48:40,986: INFO: common: yaml file : params.yaml loaded successfully]
[2025-01-01 22:48:40,989: INFO: common: yaml file : schema.yaml loaded successfully]
[2025-01-01 22:48:40,990: INFO: common: created directory at artifacts]
[2025-01-01 22:48:40,991: INFO: common: created directory at artifacts/data_validation]
[2025-01-01 22:48:41,002: INFO: main: >>>>>stage DATA VALIDATION STAGE completed <<<<<<<]
[2025-01-01 22:48:41,009: INFO: main: >>>>>>stage DATA TRANSFORMATION STAGE started<<<<<<]
[2025-01-01 22:48:41,012: INFO: common: yaml file : config\config.yaml loaded successfully]
[2025-01-01 22:48:41,014: INFO: common: yaml file : params.yaml loaded successfully]
[2025-01-01 22:48:41,017: INFO: common: yaml file : schema.yaml loaded successfully]
[2025-01-01 22:48:41,018: INFO: common: created directory at artifacts]
[2025-01-01 22:48:41,019: INFO: common: created directory at artifacts/data_transformation]
[2025-01-01 22:48:41,038: INFO: data_transformation: Splitted the data into train and test]
[2025-01-01 22:48:41,038: INFO: data_transformation: (1199, 12)]
[2025-01-01 22:48:41,039: INFO: data_transformation: (400, 12)]
[2025-01-01 22:48:41,039: INFO: main: >>>>>stage DATA TRANSFORMATION STAGE completed <<<<<<<]
[2025-01-01 22:48:41,040: INFO: main: >>>>>>stage MODEL TRAINING STAGE started<<<<<<]
[2025-01-01 22:48:41,043: INFO: common: yaml file : config\config.yaml loaded successfully]
[2025-01-01 22:48:41,051: INFO: common: yaml file : params.yaml loaded successfully]
[2025-01-01 22:48:41,053: INFO: common: yaml file : schema.yaml loaded successfully]
[2025-01-01 22:48:41,054: INFO: common: created directory at artifacts]
[2025-01-01 22:48:41,054: INFO: common: created directory at artifacts/model_trainer]
[2025-01-01 22:48:41,067: INFO: main: >>>>>stage MODEL TRAINING STAGE completed <<<<<<<]
[2025-01-01 22:48:41,068: INFO: main: >>>>>>stage MODEL EVALUATION STAGE started<<<<<<]
[2025-01-01 22:48:41,071: INFO: common: yaml file : config\config.yaml loaded successfully]
[2025-01-01 22:48:41,071: INFO: common: yaml file : params.yaml loaded successfully]
[2025-01-01 22:48:41,073: INFO: common: yaml file : schema.yaml loaded successfully]
[2025-01-01 22:48:41,074: INFO: common: created directory at artifacts]
[2025-01-01 22:48:41,081: INFO: common: created directory at artifacts/model_evaluation]
[2025-01-01 22:48:42,079: INFO: common: json file saved at artifacts\model_evaluation\metrics.json]
[2025-01-01 22:48:55,999: INFO: main: >>>>>stage MODEL EVALUATION STAGE completed <<<<<<<]
